Workbook

Sheet Read Me
A1: BRUIN / TestPAC Yield Investigation Workbook
A3: Purpose | B3: Investigate Apache and Odyssey yield discrepancies at TestPAC and provide management dashboards.
A4: Source 1 | B4: Apache File.xlsx — 24 operators × 32 days of lot yields.
A5: Source 2 | B5: Odyssey File.xlsx — 24 operators × 32 days of lot yields.
A6: Source 3 | B6: Solar Intensity and Humidity - UCLA.xlsx — daily solar intensity and humidity.
A7: Case facts | B7: Each lot contains 10,000 units; Apache ASP = $175; Odyssey ASP = $145; claimed TestPAC energy savings = $1.25M over 32 days.
A8: Operator test | B8: Operator abnormality is flagged when the operator's average yield is at least 3 standard deviations below the operator-average distribution.
A9: Environment model | B9: Multiple linear model: daily average yield = intercept + solar coefficient × solar intensity + humidity coefficient × humidity.
A10: Financial scenario | B10: Ideal-facility scenario uses Solar Intensity = 99 and Humidity = 0. Apache environmental model excludes Barbara to avoid mixing the operator anomaly with facility effects.
A12: Important: the ideal-facility financial comparison is a modeled scenario because the case does not provide observed yields from a separate perfectly controlled facility. The operator financial estimate uses the operator's shortfall versus the average of the other 23 operators.
A16: How to read R² | B16: R² is NOT yield. It measures how closely day-to-day yield variation is associated with solar intensity and humidity in the model.
A17: Example | B17: Apache R² = 99.5% means the model explains about 99.5% of Apache's day-to-day yield variation; it does not mean Apache yields 99.5% or is unaffected by weather.

Sheet Apache Raw
A1: Operator | B1: Day 1 | C1: Day 2 | D1: Day 3 | E1: Day 4 | F1: Day 5 | G1: Day 6 | H1: Day 7 | I1: Day 8 | J1: Day 9 | K1: Day 10 | L1: Day 11 | M1: Day 12 | N1: Day 13 | O1: Day 14 | P1: Day 15 | Q1: Day 16 | R1: Day 17 | S1: Day 18 | T1: Day 19 | U1: Day 20 | V1: Day 21 | W1: Day 22 | X1: Day 23 | Y1: Day 24 | Z1: Day 25 | AA1: Day 26 | AB1: Day 27 | AC1: Day 28 | AD1: Day 29 | AE1: Day 30 | AF1: Day 31 | AG1: Day 32
A2: James | B2: 95.479 | C2: 95.1605 | D2: 94.8755 | E2: 95.3055 | F2: 95.7065 | G2: 95.4785 | H2: 95.115 | I2: 95.937 | J2: 95.263 | K2: 95.0975 | L2: 95.506 | M2: 95.2225 | N2: 95.5565 | O2: 95.2015 | P2: 95.6425 | Q2: 95.188 | R2: 95.5145 | S2: 95.3895 | T2: 95.016 | U2: 95.647 | V2: 95.1865 | W2: 95.393 | X2: 95.602 | Y2: 95.2655 | Z2: 95.6505 | AA2: 95.1245 | AB2: 94.778 | AC2: 95.55 | AD2: 95.0605 | AE2: 95.315 | AF2: 95.1605 | AG2: 95.0135
A3: Michael | B3: 95.579 | C3: 95.0905 | D3: 95.0155 | E3: 95.1555 | F3: 95.6165 | G3: 95.6885 | H3: 94.955 | I3: 95.637 | J3: 95.423 | K3: 95.0275 | L3: 95.346 | M3: 94.9725 | N3: 95.3565 | O3: 95.0815 | P3: 95.6725 | Q3: 95.158 | R3: 95.4145 | S3: 95.4395 | T3: 95.046 | U3: 95.457 | V3: 95.0265 | W3: 95.353 | X3: 95.562 | Y3: 95.0655 | Z3: 95.4305 | AA3: 95.3245 | AB3: 95.068 | AC3: 95.37 | AD3: 94.9505 | AE3: 95.345 | AF3: 95.3105 | AG3: 94.9635
A4: John | B4: 95.429 | C4: 94.9205 | D4: 94.9555 | E4: 95.3255 | F4: 95.8065 | G4: 95.5185 | H4: 94.895 | I4: 95.857 | J4: 95.193 | K4: 94.9975 | L4: 95.446 | M4: 94.9225 | N4: 95.2665 | O4: 95.0615 | P4: 95.6225 | Q4: 95.238 | R4: 95.5545 | S4: 95.4895 | T4: 94.956 | U4: 95.617 | V4: 95.3565 | W4: 95.573 | X4: 95.792 | Y4: 95.3555 | Z4: 95.7005 | AA4: 95.2945 | AB4: 94.918 | AC4: 95.38 | AD4: 94.7705 | AE4: 95.475 | AF4: 95.0805 | AG4: 94.8735
A5: Robert | B5: 95.599 | C5: 95.0505 | D5: 95.0655 | E5: 95.3655 | F5: 95.6865 | G5: 95.6485 | H5: 94.895 | I5: 95.597 | J5: 95.173 | K5: 95.1175 | L5: 95.476 | M5: 95.1125 | N5: 95.4165 | O5: 95.2715 | P5: 95.6225 | Q5: 95.038 | R5: 95.5045 | S5: 95.4395 | T5: 94.896 | U5: 95.537 | V5: 95.0265 | W5: 95.173 | X5: 95.562 | Y5: 95.1755 | Z5: 95.6205 | AA5: 95.0345 | AB5: 95.078 | AC5: 95.49 | AD5: 94.9605 | AE5: 95.245 | AF5: 95.0905 | AG5: 94.9635
A6: David | B6: 95.469 | C6: 95.0105 | D6: 95.0755 | E6: 95.1855 | F6: 95.5665 | G6: 95.7185 | H6: 95.055 | I6: 95.607 | J6: 95.343 | K6: 95.0275 | L6: 95.656 | M6: 94.8825 | N6: 95.5065 | O6: 95.3215 | P6: 95.4225 | Q6: 95.108 | R6: 95.5345 | S6: 95.5395 | T6: 95.026 | U6: 95.417 | V6: 95.0265 | W6: 95.213 | X6: 95.872 | Y6: 95.3655 | Z6: 95.4405 | AA6: 95.3345 | AB6: 95.028 | AC6: 95.46 | AD6: 94.7105 | AE6: 95.185 | AF6: 95.1005 | AG6: 94.9735
A7: William | B7: 95.419 | C7: 95.0105 | D7: 94.9455 | E7: 95.2755 | F7: 95.7865 | G7: 95.7385 | H7: 95.065 | I7: 95.747 | J7: 95.163 | K7: 94.9075 | L7: 95.546 | M7: 95.2125 | N7: 95.2465 | O7: 95.2815 | P7: 95.7025 | Q7: 95.238 | R7: 95.6045 | S7: 95.7195 | T7: 95.066 | U7: 95.317 | V7: 95.2465 | W7: 95.313 | X7: 95.612 | Y7: 95.1955 | Z7: 95.5805 | AA7: 95.1545 | AB7: 94.828 | AC7: 95.27 | AD7: 95.0705 | AE7: 95.365 | AF7: 95.2305 | AG7: 95.0535
A8: Richard | B8: 95.319 | C8: 94.8405 | D8: 94.8255 | E8: 95.1155 | F8: 95.6365 | G8: 95.5385 | H8: 95.155 | I8: 95.707 | J8: 95.393 | K8: 94.8875 | L8: 95.386 | M8: 95.1925 | N8: 95.3865 | O8: 95.2515 | P8: 95.5825 | Q8: 95.148 | R8: 95.6045 | S8: 95.4195 | T8: 94.966 | U8: 95.417 | V8: 95.1565 | W8: 95.363 | X8: 95.732 | Y8: 95.2955 | Z8: 95.5005 | AA8: 95.0545 | AB8: 95.018 | AC8: 95.23 | AD8: 94.7505 | AE8: 95.325 | AF8: 95.2205 | AG8: 94.8935
A9: Joseph | B9: 95.549 | C9: 94.8805 | D9: 95.0155 | E9: 95.3155 | F9: 95.5865 | G9: 95.4885 | H9: 95.115 | I9: 95.947 | J9: 95.103 | K9: 95.0575 | L9: 95.576 | M9: 95.0525 | N9: 95.2865 | O9: 95.1215 | P9: 95.5825 | Q9: 94.988 | R9: 95.2445 | S9: 95.4395 | T9: 95.066 | U9: 95.527 | V9: 95.2565 | W9: 95.533 | X9: 95.522 | Y9: 95.2555 | Z9: 95.5605 | AA9: 95.3145 | AB9: 94.758 | AC9: 95.18 | AD9: 94.7305 | AE9: 95.475 | AF9: 95.2105 | AG9: 95.1435
A10: Thomas | B10: 95.479 | C10: 94.8705 | D10: 94.8555 | E10: 95.3755 | F10: 95.8365 | G10: 95.5785 | H10: 95.075 | I10: 95.587 | J10: 95.403 | K10: 94.7875 | L10: 95.576 | M10: 94.9225 | N10: 95.3365 | O10: 95.3315 | P10: 95.7425 | Q10: 95.068 | R10: 95.2945 | S10: 95.6795 | T10: 95.146 | U10: 95.637 | V10: 95.0365 | W10: 95.463 | X10: 95.642 | Y10: 95.3155 | Z10: 95.7705 | AA10: 95.1145 | AB10: 94.948 | AC10: 95.41 | AD10: 94.8605 | AE10: 95.115 | AF10: 95.0605 | AG10: 94.7735
A11: Christopher | B11: 95.429 | C11: 94.9005 | D11: 94.8155 | E11: 95.1955 | F11: 95.5365 | G11: 95.4285 | H11: 95.165 | I11: 95.867 | J11: 95.263 | K11: 94.9975 | L11: 95.296 | M11: 95.2125 | N11: 95.4165 | O11: 95.0515 | P11: 95.8025 | Q11: 95.298 | R11: 95.3145 | S11: 95.5395 | T11: 94.886 | U11: 95.327 | V11: 95.3365 | W11: 95.523 | X11: 95.762 | Y11: 95.0855 | Z11: 95.5505 | AA11: 95.0945 | AB11: 94.998 | AC11: 95.32 | AD11: 94.7205 | AE11: 95.245 | AF11: 95.2205 | AG11: 95.0135
A12: Mary | B12: 95.259 | C12: 95.1605 | D12: 94.8355 | E12: 95.1055 | F12: 95.7165 | G12: 95.3885 | H12: 95.105 | I12: 95.887 | J12: 95.043 | K12: 95.0575 | L12: 95.466 | M12: 95.0725 | N12: 95.4565 | O12: 95.0615 | P12: 95.7825 | Q12: 95.098 | R12: 95.5045 | S12: 95.3295 | T12: 95.116 | U12: 95.587 | V12: 95.0765 | W12: 95.513 | X12: 95.762 | Y12: 95.3555 | Z12: 95.7705 | AA12: 95.1845 | AB12: 95.118 | AC12: 95.17 | AD12: 94.8405 | AE12: 95.185 | AF12: 95.1605 | AG12: 94.8435
A13: Patricia | B13: 95.409 | C13: 94.9105 | D13: 94.9355 | E13: 95.1355 | F13: 95.6765 | G13: 95.7285 | H13: 94.925 | I13: 95.667 | J13: 95.043 | K13: 94.7475 | L13: 95.656 | M13: 95.0425 | N13: 95.3765 | O13: 95.3015 | P13: 95.5225 | Q13: 95.018 | R13: 95.2945 | S13: 95.4195 | T13: 95.056 | U13: 95.667 | V13: 95.1665 | W13: 95.323 | X13: 95.722 | Y13: 95.1255 | Z13: 95.7505 | AA13: 95.1945 | AB13: 95.118 | AC13: 95.43 | AD13: 94.8505 | AE13: 95.305 | AF13: 95.0705 | AG13: 95.0035
... A25: Amanda | B25: 95.529 | C25: 94.8705 | D25: 95.1355 | E25: 94.9955 | F25: 95.5365 | G25: 95.5085 | H25: 95.045 | I25: 95.887 | J25: 95.383 | K25: 94.8775 | L25: 95.386 | M25: 95.1225 | N25: 95.5665 | O25: 94.9715 | P25: 95.4925 | Q25: 94.928 | R25: 95.4145 | S25: 95.7095 | T25: 94.926 | U25: 95.297 | V25: 95.1765 | W25: 95.523 | X25: 95.522 | Y25: 95.0155 | Z25: 95.5105 | AA25: 95.2845 | AB25: 94.748 | AC25: 95.27 | AD25: 94.9405 | AE25: 95.475 | AF25: 95.1605 | AG25: 94.9635

Sheet Odyssey Raw
A1: Operator | B1: Day 1 | C1: Day 2 | D1: Day 3 | E1: Day 4 | F1: Day 5 | G1: Day 6 | H1: Day 7 | I1: Day 8 | J1: Day 9 | K1: Day 10 | L1: Day 11 | M1: Day 12 | N1: Day 13 | O1: Day 14 | P1: Day 15 | Q1: Day 16 | R1: Day 17 | S1: Day 18 | T1: Day 19 | U1: Day 20 | V1: Day 21 | W1: Day 22 | X1: Day 23 | Y1: Day 24 | Z1: Day 25 | AA1: Day 26 | AB1: Day 27 | AC1: Day 28 | AD1: Day 29 | AE1: Day 30 | AF1: Day 31 | AG1: Day 32
A2: James | B2: 97.1525 | C2: 97.1005 | D2: 96.992 | E2: 97.1775 | F2: 97.3595 | G2: 97.0515 | H2: 96.995 | I2: 97.232 | J2: 97.1095 | K2: 96.831 | L2: 97.1885 | M2: 97.186 | N2: 97.091 | O2: 96.898 | P2: 97.1925 | Q2: 97.017 | R2: 96.991 | S2: 97.1825 | T2: 97.067 | U2: 97.3225 | V2: 96.9655 | W2: 97.2845 | X2: 97.3725 | Y2: 97.1565 | Z2: 97.3485 | AA2: 97.14 | AB2: 97.0365 | AC2: 96.916 | AD2: 96.838 | AE2: 97.158 | AF2: 97.254 | AG2: 96.9355
A3: Michael | B3: 97.0525 | C3: 96.8405 | D3: 96.802 | E3: 97.1575 | F3: 97.1595 | G3: 97.2215 | H3: 96.935 | I3: 97.352 | J3: 96.9995 | K3: 97.111 | L3: 97.3585 | M3: 96.956 | N3: 97.171 | O3: 97.218 | P3: 97.3625 | Q3: 96.947 | R3: 97.101 | S3: 97.2725 | T3: 96.927 | U3: 96.9825 | V3: 97.1255 | W3: 97.3245 | X3: 97.3125 | Y3: 96.9865 | Z3: 97.3885 | AA3: 97.03 | AB3: 97.0465 | AC3: 97.306 | AD3: 96.808 | AE3: 97.228 | AF3: 97.214 | AG3: 96.9555
A4: John | B4: 97.1525 | C4: 96.8605 | D4: 96.922 | E4: 97.0375 | F4: 97.3495 | G4: 97.0215 | H4: 97.055 | I4: 97.192 | J4: 96.9795 | K4: 97.171 | L4: 97.1785 | M4: 97.196 | N4: 97.321 | O4: 97.078 | P4: 97.3625 | Q4: 97.237 | R4: 97.151 | S4: 97.2425 | T4: 97.187 | U4: 97.0625 | V4: 97.2655 | W4: 97.2745 | X4: 97.2325 | Y4: 96.8865 | Z4: 97.1885 | AA4: 97.24 | AB4: 96.8765 | AC4: 97.156 | AD4: 97.168 | AE4: 97.208 | AF4: 96.924 | AG4: 96.9855
A5: Robert | B5: 97.1125 | C5: 96.9805 | D5: 96.852 | E5: 96.9475 | F5: 97.1795 | G5: 97.3615 | H5: 96.855 | I5: 97.252 | J5: 97.0595 | K5: 97.131 | L5: 97.0885 | M5: 97.096 | N5: 97.081 | O5: 96.908 | P5: 97.1325 | Q5: 97.157 | R5: 97.331 | S5: 97.2625 | T5: 96.967 | U5: 97.2225 | V5: 97.0655 | W5: 96.9545 | X5: 97.3525 | Y5: 97.2165 | Z5: 97.0585 | AA5: 97.08 | AB5: 96.8565 | AC5: 97.296 | AD5: 96.808 | AE5: 97.268 | AF5: 96.874 | AG5: 97.0055
A6: David | B6: 97.0725 | C6: 96.8205 | D6: 97.142 | E6: 96.9375 | F6: 97.2595 | G6: 97.2715 | H6: 97.115 | I6: 97.072 | J6: 96.9795 | K6: 97.051 | L6: 97.3085 | M6: 96.866 | N6: 97.061 | O6: 96.978 | P6: 97.0925 | Q6: 97.237 | R6: 97.111 | S6: 97.1625 | T6: 96.997 | U6: 97.0425 | V6: 97.2355 | W6: 97.2445 | X6: 97.2625 | Y6: 97.1065 | Z6: 97.2985 | AA6: 97 | AB6: 96.8565 | AC6: 96.946 | AD6: 96.978 | AE6: 96.948 | AF6: 97.004 | AG6: 96.9155
A7: William | B7: 97.1225 | C7: 97.1805 | D7: 97.012 | E7: 97.0575 | F7: 97.3495 | G7: 97.3515 | H7: 96.855 | I7: 97.182 | J7: 96.8895 | K7: 97.001 | L7: 97.1685 | M7: 97.036 | N7: 97.031 | O7: 97.208 | P7: 97.3025 | Q7: 97.177 | R7: 97.181 | S7: 97.1325 | T7: 96.837 | U7: 97.0725 | V7: 96.9355 | W7: 97.2445 | X7: 97.3725 | Y7: 97.1365 | Z7: 97.1185 | AA7: 97.07 | AB7: 97.0565 | AC7: 97.256 | AD7: 97.098 | AE7: 97.248 | AF7: 97.254 | AG7: 97.1355
A8: Richard | B8: 96.9725 | C8: 96.9205 | D8: 96.792 | E8: 96.9775 | F8: 97.0495 | G8: 97.2215 | H8: 97.095 | I8: 97.262 | J8: 96.9095 | K8: 96.831 | L8: 97.2085 | M8: 96.946 | N8: 97.091 | O8: 96.998 | P8: 97.2525 | Q8: 96.987 | R8: 97.301 | S8: 97.1225 | T8: 97.097 | U8: 97.3525 | V8: 97.2155 | W8: 96.9845 | X8: 97.3125 | Y8: 97.0965 | Z8: 97.2685 | AA8: 97.11 | AB8: 97.1465 | AC8: 97.296 | AD8: 96.968 | AE8: 97.238 | AF8: 97.184 | AG8: 97.0355
A9: Joseph | B9: 97.1525 | C9: 96.8305 | D9: 97.102 | E9: 97.0675 | F9: 97.1295 | G9: 97.1115 | H9: 97.125 | I9: 97.212 | J9: 97.0995 | K9: 97.051 | L9: 97.2985 | M9: 96.996 | N9: 96.961 | O9: 96.958 | P9: 97.1025 | Q9: 97.097 | R9: 97.141 | S9: 97.0425 | T9: 97.147 | U9: 97.1625 | V9: 96.9955 | W9: 97.1445 | X9: 97.1325 | Y9: 97.0165 | Z9: 97.1785 | AA9: 96.93 | AB9: 96.8965 | AC9: 97.286 | AD9: 96.948 | AE9: 96.978 | AF9: 97.164 | AG9: 96.8555
A10: Thomas | B10: 97.0425 | C10: 96.9905 | D10: 96.862 | E10: 97.2475 | F10: 97.3595 | G10: 97.2215 | H10: 97.175 | I10: 97.032 | J10: 97.2395 | K10: 96.871 | L10: 97.2685 | M10: 97.136 | N10: 96.981 | O10: 96.918 | P10: 97.2525 | Q10: 96.887 | R10: 97.021 | S10: 97.3625 | T10: 96.947 | U10: 97.1025 | V10: 96.8955 | W10: 97.2245 | X10: 97.0325 | Y10: 97.0865 | Z10: 97.1885 | AA10: 97.25 | AB10: 97.0465 | AC10: 97.206 | AD10: 97.188 | AE10: 97.078 | AF10: 97.244 | AG10: 97.1255
A11: Christopher | B11: 97.0325 | C11: 97.0105 | D11: 97.062 | E11: 97.1675 | F11: 97.0295 | G11: 97.0515 | H11: 97.085 | I11: 97.302 | J11: 96.8995 | K11: 97.141 | L11: 97.0485 | M11: 96.976 | N11: 97.261 | O11: 96.948 | P11: 97.0425 | Q11: 97.257 | R11: 97.141 | S11: 97.3825 | T11: 97.077 | U11: 97.1525 | V11: 97.1055 | W11: 97.0245 | X11: 97.1025 | Y11: 96.9265 | Z11: 97.2585 | AA11: 97.04 | AB11: 96.8565 | AC11: 96.996 | AD11: 97.028 | AE11: 97.118 | AF11: 96.884 | AG11: 97.0355
A12: Mary | B12: 96.9725 | C12: 97.1805 | D12: 96.832 | E12: 96.9975 | F12: 97.2395 | G12: 97.2415 | H12: 97.025 | I12: 97.262 | J12: 97.0895 | K12: 97.091 | L12: 97.1085 | M12: 96.846 | N12: 97.351 | O12: 96.898 | P12: 97.3925 | Q12: 96.867 | R12: 97.101 | S12: 97.3025 | T12: 97.037 | U12: 97.1725 | V12: 97.0155 | W12: 97.0845 | X12: 97.0025 | Y12: 97.2165 | Z12: 97.3185 | AA12: 97.09 | AB12: 96.8165 | AC12: 97.016 | AD12: 97.128 | AE12: 96.928 | AF12: 97.144 | AG12: 97.0055
A13: Patricia | B13: 97.3325 | C13: 96.9605 | D13: 96.802 | E13: 96.9775 | F13: 97.0895 | G13: 97.0115 | H13: 96.955 | I13: 97.072 | J13: 97.2195 | K13: 97.071 | L13: 97.0285 | M13: 97.026 | N13: 97.281 | O13: 96.968 | P13: 96.9925 | Q13: 96.917 | R13: 97.001 | S13: 97.0325 | T13: 97.177 | U13: 97.0825 | V13: 96.9755 | W13: 97.0545 | X13: 97.1225 | Y13: 97.0965 | Z13: 97.3285 | AA13: 97.01 | AB13: 97.1965 | AC13: 97.196 | AD13: 96.828 | AE13: 97.188 | AF13: 97.154 | AG13: 97.1155
... A25: Amanda | B25: 97.2325 | C25: 97.1905 | D25: 97.092 | E25: 97.1775 | F25: 97.0395 | G25: 97.1515 | H25: 97.105 | I25: 97.122 | J25: 97.0595 | K25: 96.801 | L25: 97.3085 | M25: 97.176 | N25: 97.321 | O25: 97.198 | P25: 97.3125 | Q25: 97.077 | R25: 97.321 | S25: 97.3625 | T25: 97.097 | U25: 97.1825 | V25: 96.9555 | W25: 97.2045 | X25: 97.2325 | Y25: 96.9665 | Z25: 97.2985 | AA25: 96.89 | AB25: 96.9965 | AC25: 97.296 | AD25: 97.088 | AE25: 97.288 | AF25: 96.924 | AG25: 96.9055

Sheet Weather Raw
A1: Metric | B1: Day 1 | C1: Day 2 | D1: Day 3 | E1: Day 4 | F1: Day 5 | G1: Day 6 | H1: Day 7 | I1: Day 8 | J1: Day 9 | K1: Day 10 | L1: Day 11 | M1: Day 12 | N1: Day 13 | O1: Day 14 | P1: Day 15 | Q1: Day 16 | R1: Day 17 | S1: Day 18 | T1: Day 19 | U1: Day 20 | V1: Day 21 | W1: Day 22 | X1: Day 23 | Y1: Day 24 | Z1: Day 25 | AA1: Day 26 | AB1: Day 27 | AC1: Day 28 | AD1: Day 29 | AE1: Day 30 | AF1: Day 31 | AG1: Day 32
A2: Solar Intensity | B2: 64 | C2: 5 | D2: 1 | E2: 23 | F2: 77 | G2: 97 | H2: 10 | I2: 90 | J2: 36 | K2: 9 | L2: 70 | M2: 19 | N2: 83 | O2: 21 | P2: 85 | Q2: 36 | R2: 71 | S2: 87 | T2: 4 | U2: 92 | V2: 41 | W2: 76 | X2: 82 | Y2: 39 | Z2: 97 | AA2: 27 | AB2: 14 | AC2: 44 | AD2: 15 | AE2: 62 | AF2: 39 | AG2: 23
A3: Humidity | B3: 35 | C3: 4 | D3: 21 | E3: 0 | F3: 6 | G3: 82 | H3: 20 | I3: 6 | J3: 21 | K3: 43 | L3: 33 | M3: 43 | N3: 93 | O3: 9 | P3: 40 | Q3: 66 | R3: 53 | S3: 70 | T3: 26 | U3: 95 | V3: 54 | W3: 91 | X3: 5 | Y3: 42 | Z3: 68 | AA3: 15 | AB3: 57 | AC3: 8 | AD3: 79 | AE3: 74 | AF3: 47 | AG3: 84

Sheet Assumptions & Model
A1: Assumptions, Environmental Model & Financial Scenario
A3: Units per lot | B3: 10000
A4: Days | B4: 32
A5: Operators | B5: 24
A6: Apache ASP | B6: 175
A7: Odyssey ASP | B7: 145
A8: TestPAC energy savings | B8: 1250000
A9: Ideal solar / power index | B9: 99
A10: Ideal humidity | B10: 0
A12: Daily mean solar | B12: =AVERAGE('Daily Analysis'!$B$2:$B$33) -> 48.09375
A13: Daily mean humidity | B13: =AVERAGE('Daily Analysis'!$C$2:$C$33) -> 43.4375
A14: Apache mean yield ex-Barbara | B14: =AVERAGE('Daily Analysis'!$E$2:$E$33) -> 95.280006
A15: Odyssey mean yield | B15: =AVERAGE('Daily Analysis'!$F$2:$F$33) -> 97.099271
A17: Var(Solar) | B17: =SUMPRODUCT(('Daily Analysis'!$B$2:$B$33-$B$12)*('Daily Analysis'!$B$2:$B$33-$B$12))/$B$4 -> 995.08496
A18: Var(Humidity) | B18: =SUMPRODUCT(('Daily Analysis'!$C$2:$C$33-$B$13)*('Daily Analysis'!$C$2:$C$33-$B$13))/$B$4 -> 873.55859
A19: Cov(Solar,Humidity) | B19: =SUMPRODUCT(('Daily Analysis'!$B$2:$B$33-$B$12)*('Daily Analysis'!$C$2:$C$33-$B$13))/$B$4 -> 315.77148
A20: Cov(Apache,Solar) | B20: =SUMPRODUCT(('Daily Analysis'!$E$2:$E$33-$B$14)*('Daily Analysis'!$B$2:$B$33-$B$12))/$B$4 -> 7.4430477
A21: Cov(Apache,Humidity) | B21: =SUMPRODUCT(('Daily Analysis'!$E$2:$E$33-$B$14)*('Daily Analysis'!$C$2:$C$33-$B$13))/$B$4 -> 0.015514988
A22: Cov(Odyssey,Solar) | B22: =SUMPRODUCT(('Daily Analysis'!$F$2:$F$33-$B$15)*('Daily Analysis'!$B$2:$B$33-$B$12))/$B$4 -> 2.3112923
A23: Cov(Odyssey,Humidity) | B23: =SUMPRODUCT(('Daily Analysis'!$F$2:$F$33-$B$15)*('Daily Analysis'!$C$2:$C$33-$B$13))/$B$4 -> 0.36428516
A25: Regression denominator | B25: =$B$17*$B$18-$B$19^2 -> 769553.39
A26: Apache solar coefficient | B26: =($B$20*$B$18-$B$21*$B$19)/$B$25 -> 0.0084426099
A27: Apache humidity coefficient | B27: =($B$21*$B$17-$B$20*$B$19)/$B$25 -> -0.00303405
A28: Apache intercept | B28: =$B$14-$B$26*$B$12-$B$27*$B$13 -> 95.005761
A29: Odyssey solar coefficient | B29: =($B$22*$B$18-$B$23*$B$19)/$B$25 -> 0.0024741862
A30: Odyssey humidity coefficient | B30: =($B$23*$B$17-$B$22*$B$19)/$B$25 -> -0.00047734898
A31: Odyssey intercept | B31: =$B$15-$B$29*$B$12-$B$30*$B$13 -> 97.001013
A32: Apache modeled ideal yield | B32: =$B$28+$B$26*$B$9+$B$27*$B$10 -> 95.841579
A33: Odyssey modeled ideal yield | B33: =$B$31+$B$29*$B$9+$B$30*$B$10 -> 97.245957
A35: Apache yield variation explained by weather (R²) | B35: =1-SUMPRODUCT('Daily Analysis'!$K$2:$K$33,'Daily Analysis'!$K$2:$K$33)/SUMPRODUCT(('Daily Analysis'!$E$2:$E$33-$B$14)*('Daily Analysis'!$E$2:$E$33-$B$14)) -> 0.99453052
A36: Odyssey yield variation explained by weather (R²) | B36: =1-SUMPRODUCT('Daily Analysis'!$L$2:$L$33,'Daily Analysis'!$L$2:$L$33)/SUMPRODUCT(('Daily Analysis'!$F$2:$F$33-$B$15)*('Daily Analysis'!$F$2:$F$33-$B$15)) -> 0.91862314
A38: Apache environmental yield gap | B38: =MAX(0,$B$32-$B$14) -> 0.56157316
A39: Apache environmental lost units | B39: =$B$38/100*$B$3*$B$4*$B$5 -> 43128.819
A40: Apache environmental revenue impact | B40: =$B$39*$B$6 -> 7547543.2
A41: Odyssey environmental yield gap | B41: =MAX(0,$B$33-$B$15) -> 0.14668639
A42: Odyssey environmental lost units | B42: =$B$41/100*$B$3*$B$4*$B$5 -> 11265.515
A43: Odyssey environmental revenue impact | B43: =$B$42*$B$7 -> 1633499.6
A44: Barbara Apache yield shortfall | B44: {=MAX(0,-INDEX('Operator Analysis'!$D$2:$D$25,MATCH("Barbara",'Operator Analysis'!$A$2:$A$25,0)))} -> 0.23839674
A45: Barbara estimated lost units | B45: =$B$44/100*$B$3*$B$4 -> 762.86957
A46: Barbara estimated revenue impact | B46: =$B$45*$B$6 -> 133502.17
...

Sheet Daily Analysis
A1: Day | B1: Solar Intensity | C1: Humidity | D1: Apache Avg Yield | E1: Apache Avg ex-Barbara | F1: Odyssey Avg Yield | G1: Solar Band | H1: Humidity Band | I1: Apache Predicted | J1: Odyssey Predicted | K1: Apache Residual | L1: Odyssey Residual | N1: Solar Band | O1: Apache Avg Yield | P1: Odyssey Avg Yield | Q1: Days | S1: Humidity Band | T1: Apache Avg Yield | U1: Odyssey Avg Yield | V1: Days
A2: 1 | B2: 64 | C2: 35 | D2: =AVERAGE('Apache Raw'!B$2:B$25) -> 95.449417 | E2: =(SUM('Apache Raw'!B$2:B$25)-'Apache Raw'!B$17)/('Assumptions & Model'!$B$5-1) -> 95.460739 | F2: =AVERAGE('Odyssey Raw'!B$2:B$25) -> 97.15625 | G2: =IF(B2<33,"Low",IF(B2<67,"Medium","High")) -> Medium | H2: =IF(C2<33,"Low",IF(C2<67,"Medium","High")) -> Medium | I2: ='Assumptions & Model'!$B$28+'Assumptions & Model'!$B$26*B2+'Assumptions & Model'!$B$27*C2 -> 95.439896 | J2: ='Assumptions & Model'!$B$31+'Assumptions & Model'!$B$29*B2+'Assumptions & Model'!$B$30*C2 -> 97.142653 | K2: =E2-I2 -> 0.020842956 | L2: =F2-J2 -> 0.01359651 | N2: Low | O2: =AVERAGEIF($G$2:$G$33,N2,$D$2:$D$33) -> 95.017333 | P2: =AVERAGEIF($G$2:$G$33,N2,$F$2:$F$33) -> 97.022424 | Q2: =COUNTIF($G$2:$G$33,N2) -> 12 | S2: Low | T2: =AVERAGEIF($H$2:$H$33,S2,$D$2:$D$33) -> 95.251486 | U2: =AVERAGEIF($H$2:$H$33,S2,$F$2:$F$33) -> 97.07975 | V2: =COUNTIF($H$2:$H$33,S2) -> 12
A3: 2 | B3: 5 | C3: 4 | D3: =AVERAGE('Apache Raw'!C$2:C$25) -> 95.013 | E3: =(SUM('Apache Raw'!C$2:C$25)-'Apache Raw'!C$17)/('Assumptions & Model'!$B$5-1) -> 95.027891 | F3: =AVERAGE('Odyssey Raw'!C$2:C$25) -> 96.972583 | G3: =IF(B3<33,"Low",IF(B3<67,"Medium","High")) -> Low | H3: =IF(C3<33,"Low",IF(C3<67,"Medium","High")) -> Low | I3: ='Assumptions & Model'!$B$28+'Assumptions & Model'!$B$26*B3+'Assumptions & Model'!$B$27*C3 -> 95.035838 | J3: ='Assumptions & Model'!$B$31+'Assumptions & Model'!$B$29*B3+'Assumptions & Model'!$B$30*C3 -> 97.011474 | K3: =E3-I3 -> -0.0079464373 | L3: =F3-J3 -> -0.038890987 | N3: Medium | O3: =AVERAGEIF($G$2:$G$33,N3,$D$2:$D$33) -> 95.246667 | P3: =AVERAGEIF($G$2:$G$33,N3,$F$2:$F$33) -> 97.089615 | Q3: =COUNTIF($G$2:$G$33,N3) -> 8 | S3: Medium | T3: =AVERAGEIF($H$2:$H$33,S3,$D$2:$D$33) -> 95.235841 | U3: =AVERAGEIF($H$2:$H$33,S3,$F$2:$F$33) -> 97.092364 | V3: =COUNTIF($H$2:$H$33,S3) -> 11
A4: 3 | B4: 1 | C4: 21 | D4: =AVERAGE('Apache Raw'!D$2:D$25) -> 94.924667 | E4: =(SUM('Apache Raw'!D$2:D$25)-'Apache Raw'!D$17)/('Assumptions & Model'!$B$5-1) -> 94.93637 | F4: =AVERAGE('Odyssey Raw'!D$2:D$25) -> 96.974083 | G4: =IF(B4<33,"Low",IF(B4<67,"Medium","High")) -> Low | H4: =IF(C4<33,"Low",IF(C4<67,"Medium","High")) -> Low | I4: ='Assumptions & Model'!$B$28+'Assumptions & Model'!$B$26*B4+'Assumptions & Model'!$B$27*C4 -> 94.950488 | J4: ='Assumptions & Model'!$B$31+'Assumptions & Model'!$B$29*B4+'Assumptions & Model'!$B$30*C4 -> 96.993463 | K4: =E4-I4 -> -0.014118886 | L4: =F4-J4 -> -0.01937931 | N4: High | O4: =AVERAGEIF($G$2:$G$33,N4,$D$2:$D$33) -> 95.538417 | P4: =AVERAGEIF($G$2:$G$33,N4,$F$2:$F$33) -> 97.182556 | Q4: =COUNTIF($G$2:$G$33,N4) -> 12 | S4: High | T4: =AVERAGEIF($H$2:$H$33,S4,$D$2:$D$33) -> 95.336694 | U4: =AVERAGEIF($H$2:$H$33,S4,$F$2:$F$33) -> 97.133741 | V4: =COUNTIF($H$2:$H$33,S4) -> 9
A5: 4 | B5: 23 | C5: 0 | D5: =AVERAGE('Apache Raw'!E$2:E$25) -> 95.188 | E5: =(SUM('Apache Raw'!E$2:E$25)-'Apache Raw'!E$17)/('Assumptions & Model'!$B$5-1) -> 95.198543 | F5: =AVERAGE('Odyssey Raw'!E$2:E$25) -> 97.034167 | G5: =IF(B5<33,"Low",IF(B5<67,"Medium","High")) -> Low | H5: =IF(C5<33,"Low",IF(C5<67,"Medium","High")) -> Low | I5: ='Assumptions & Model'!$B$28+'Assumptions & Model'!$B$26*B5+'Assumptions & Model'!$B$27*C5 -> 95.199941 | J5: ='Assumptions & Model'!$B$31+'Assumptions & Model'!$B$29*B5+'Assumptions & Model'!$B$30*C5 -> 97.057919 | K5: =E5-I5 -> -0.0013974416 | L5: =F5-J5 -> -0.023752402
A6: 5 | B6: 77 | C6: 6 | D6: =AVERAGE('Apache Raw'!F$2:F$25) -> 95.6315 | E6: =(SUM('Apache Raw'!F$2:F$25)-'Apache Raw'!F$17)/('Assumptions & Model'!$B$5-1) -> 95.642152 | F6: =AVERAGE('Odyssey Raw'!F$2:F$25) -> 97.185333 | G6: =IF(B6<33,"Low",IF(B6<67,"Medium","High")) -> High | H6: =IF(C6<33,"Low",IF(C6<67,"Medium","High")) -> Low | I6: ='Assumptions & Model'!$B$28+'Assumptions & Model'!$B$26*B6+'Assumptions & Model'!$B$27*C6 -> 95.637638 | J6: ='Assumptions & Model'!$B$31+'Assumptions & Model'!$B$29*B6+'Assumptions & Model'!$B$30*C6 -> 97.188661 | K6: =E6-I6 -> 0.0045146197 | L6: =F6-J6 -> -0.0033276983
A7: 6 | B7: 97 | C7: 82 | D7: =AVERAGE('Apache Raw'!G$2:G$25) -> 95.583083 | E7: =(SUM('Apache Raw'!G$2:G$25)-'Apache Raw'!G$17)/('Assumptions & Model'!$B$5-1) -> 95.596761 | F7: =AVERAGE('Odyssey Raw'!G$2:G$25) -> 97.196917 | G7: =IF(B7<33,"Low",IF(B7<67,"Medium","High")) -> High | H7: =IF(C7<33,"Low",IF(C7<67,"Medium","High")) -> High | I7: ='Assumptions & Model'!$B$28+'Assumptions & Model'!$B$26*B7+'Assumptions & Model'!$B$27*C7 -> 95.575902 | J7: ='Assumptions & Model'!$B$31+'Assumptions & Model'!$B$29*B7+'Assumptions & Model'!$B$30*C7 -> 97.201866 | K7: =E7-I7 -> 0.020858919 | L7: =F7-J7 -> -0.0049495672
A8: 7 | B8: 10 | C8: 20 | D8: =AVERAGE('Apache Raw'!H$2:H$25) -> 95.016667 | E8: =(SUM('Apache Raw'!H$2:H$25)-'Apache Raw'!H$17)/('Assumptions & Model'!$B$5-1) -> 95.026304 | F8: =AVERAGE('Odyssey Raw'!H$2:H$25) -> 97.054583 | G8: =IF(B8<33,"Low",IF(B8<67,"Medium","High")) -> Low | H8: =IF(C8<33,"Low",IF(C8<67,"Medium","High")) -> Low | I8: ='Assumptions & Model'!$B$28+'Assumptions & Model'!$B$26*B8+'Assumptions & Model'!$B$27*C8 -> 95.029506 | J8: ='Assumptions & Model'!$B$31+'Assumptions & Model'!$B$29*B8+'Assumptions & Model'!$B$30*C8 -> 97.016208 | K8: =E8-I8 -> -0.0032016429 | L8: =F8-J8 -> 0.038375665
A9: 8 | B9: 90 | C9: 6 | D9: =AVERAGE('Apache Raw'!I$2:I$25) -> 95.756167 | E9: =(SUM('Apache Raw'!I$2:I$25)-'Apache Raw'!I$17)/('Assumptions & Model'!$B$5-1) -> 95.763522 | F9: =AVERAGE('Odyssey Raw'!I$2:I$25) -> 97.209917 | G9: =IF(B9<33,"Low",IF(B9<67,"Medium","High")) -> High | H9: =IF(C9<33,"Low",IF(C9<67,"Medium","High")) -> Low | I9: ='Assumptions & Model'!$B$28+'Assumptions & Model'!$B$26*B9+'Assumptions & Model'!$B$27*C9 -> 95.747391 | J9: ='Assumptions & Model'!$B$31+'Assumptions & Model'!$B$29*B9+'Assumptions & Model'!$B$30*C9 -> 97.220825 | K9: =E9-I9 -> 0.016130256 | L9: =F9-J9 -> -0.010908786
A10: 9 | B10: 36 | C10: 21 | D10: =AVERAGE('Apache Raw'!J$2:J$25) -> 95.222167 | E10: =(SUM('Apache Raw'!J$2:J$25)-'Apache Raw'!J$17)/('Assumptions & Model'!$B$5-1) -> 95.230826 | F10: =AVERAGE('Odyssey Raw'!J$2:J$25) -> 97.04575 | G10: =IF(B10<33,"Low",IF(B10<67,"Medium","High")) -> Medium | H10: =IF(C10<33,"Low",IF(C10<67,"Medium","High")) -> Low | I10: ='Assumptions & Model'!$B$28+'Assumptions & Model'!$B$26*B10+'Assumptions & Model'!$B$27*C10 -> 95.24598 | J10: ='Assumptions & Model'!$B$31+'Assumptions & Model'!$B$29*B10+'Assumptions & Model'!$B$30*C10 -> 97.080059 | K10: =E10-I10 -> -0.015153711 | L10: =F10-J10 -> -0.034309161
A11: 10 | B11: 9 | C11: 43 | D11: =AVERAGE('Apache Raw'!K$2:K$25) -> 94.967083 | E11: =(SUM('Apache Raw'!K$2:K$25)-'Apache Raw'!K$17)/('Assumptions & Model'!$B$5-1) -> 94.979674 | F11: =AVERAGE('Odyssey Raw'!K$2:K$25) -> 97.0135 | G11: =IF(B11<33,"Low",IF(B11<67,"Medium","High")) -> Low | H11: =IF(C11<33,"Low",IF(C11<67,"Medium","High")) -> Medium | I11: ='Assumptions & Model'!$B$28+'Assumptions & Model'!$B$26*B11+'Assumptions & Model'!$B$27*C11 -> 94.95128 | J11: ='Assumptions & Model'!$B$31+'Assumptions & Model'!$B$29*B11+'Assumptions & Model'!$B$30*C11 -> 97.002754 | K11: =E11-I11 -> 0.028393683 | L11: =F11-J11 -> 0.010745545
A12: 11 | B12: 70 | C12: 33 | D12: =AVERAGE('Apache Raw'!L$2:L$25) -> 95.456 | E12: =(SUM('Apache Raw'!L$2:L$25)-'Apache Raw'!L$17)/('Assumptions & Model'!$B$5-1) -> 95.472957 | F12: =AVERAGE('Odyssey Raw'!L$2:L$25) -> 97.1735 | G12: =IF(B12<33,"Low",IF(B12<67,"Medium","High")) -> High | H12: =IF(C12<33,"Low",IF(C12<67,"Medium","High")) -> Medium | I12: ='Assumptions & Model'!$B$28+'Assumptions & Model'!$B$26*B12+'Assumptions & Model'!$B$27*C12 -> 95.49662 | J12: ='Assumptions & Model'!$B$31+'Assumptions & Model'!$B$29*B12+'Assumptions & Model'!$B$30*C12 -> 97.158453 | K12: =E12-I12 -> -0.023663413 | L12: =F12-J12 -> 0.015046694
A13: 12 | B13: 19 | C13: 43 | D13: =AVERAGE('Apache Raw'!M$2:M$25) -> 95.070833 | E13: =(SUM('Apache Raw'!M$2:M$25)-'Apache Raw'!M$17)/('Assumptions & Model'!$B$5-1) -> 95.074674 | F13: =AVERAGE('Odyssey Raw'!M$2:M$25) -> 97.04475 | G13: =IF(B13<33,"Low",IF(B13<67,"Medium","High")) -> Low | H13: =IF(C13<33,"Low",IF(C13<67,"Medium","High")) -> Medium | I13: ='Assumptions & Model'!$B$28+'Assumptions & Model'!$B$26*B13+'Assumptions & Model'!$B$27*C13 -> 95.035706 | J13: ='Assumptions & Model'!$B$31+'Assumptions & Model'!$B$29*B13+'Assumptions & Model'!$B$30*C13 -> 97.027496 | K13: =E13-I13 -> 0.038967584 | L13: =F13-J13 -> 0.017253682
A14: 13 | B14: 83 | C14: 93 | D14: =AVERAGE('Apache Raw'!N$2:N$25) -> 95.373583 | E14: =(SUM('Apache Raw'!N$2:N$25)-'Apache Raw'!N$17)/('Assumptions & Model'!$B$5-1) -> 95.384761 | F14: =AVERAGE('Odyssey Raw'!N$2:N$25) -> 97.140167 | G14: =IF(B14<33,"Low",IF(B14<67,"Medium","High")) -> High | H14: =IF(C14<33,"Low",IF(C14<67,"Medium","High")) -> High | I14: ='Assumptions & Model'!$B$28+'Assumptions & Model'!$B$26*B14+'Assumptions & Model'!$B$27*C14 -> 95.424331 | J14: ='Assumptions & Model'!$B$31+'Assumptions & Model'!$B$29*B14+'Assumptions & Model'!$B$30*C14 -> 97.161977 | K14: =E14-I14 -> -0.039569992 | L14: =F14-J14 -> -0.021810121
A15: 14 | B15: 21 | C15: 9 | D15: =AVERAGE('Apache Raw'!O$2:O$25) -> 95.141083 | E15: =(SUM('Apache Raw'!O$2:O$25)-'Apache Raw'!O$17)/('Assumptions & Model'!$B$5-1) -> 95.145848 | F15: =AVERAGE('Odyssey Raw'!O$2:O$25) -> 97.01425 | G15: =IF(B15<33,"Low",IF(B15<67,"Medium","High")) -> Low | H15: =IF(C15<33,"Low",IF(C15<67,"Medium","High")) -> Low | I15: ='Assumptions & Model'!$B$28+'Assumptions & Model'!$B$26*B15+'Assumptions & Model'!$B$27*C15 -> 95.155749 | J15: ='Assumptions & Model'!$B$31+'Assumptions & Model'!$B$29*B15+'Assumptions & Model'!$B$30*C15 -> 97.048675 | K15: =E15-I15 -> -0.0099014238 | L15: =F15-J15 -> -0.034424556
A16: 15 | B16: 85 | C16: 40 | D16: =AVERAGE('Apache Raw'!P$2:P$25) -> 95.617917 | E16: =(SUM('Apache Raw'!P$2:P$25)-'Apache Raw'!P$17)/('Assumptions & Model'!$B$5-1) -> 95.629022 | F16: =AVERAGE('Odyssey Raw'!P$2:P$25) -> 97.229167 | G16: =IF(B16<33,"Low",IF(B16<67,"Medium","High")) -> High | H16: =IF(C16<33,"Low",IF(C16<67,"Medium","High")) -> Medium | I16: ='Assumptions & Model'!$B$28+'Assumptions & Model'!$B$26*B16+'Assumptions & Model'!$B$27*C16 -> 95.602021 | J16: ='Assumptions & Model'!$B$31+'Assumptions & Model'!$B$29*B16+'Assumptions & Model'!$B$30*C16 -> 97.192225 | K16: =E16-I16 -> 0.027001007 | L16: =F16-J16 -> 0.03694201
A17: 16 | B17: 36 | C17: 66 | D17: =AVERAGE('Apache Raw'!Q$2:Q$25) -> 95.106333 | E17: =(SUM('Apache Raw'!Q$2:Q$25)-'Apache Raw'!Q$17)/('Assumptions & Model'!$B$5-1) -> 95.113217 | F17: =AVERAGE('Odyssey Raw'!Q$2:Q$25) -> 97.031167 | G17: =IF(B17<33,"Low",IF(B17<67,"Medium","High")) -> Medium | H17: =IF(C17<33,"Low",IF(C17<67,"Medium","High")) -> Medium | I17: ='Assumptions & Model'!$B$28+'Assumptions & Model'!$B$26*B17+'Assumptions & Model'!$B$27*C17 -> 95.109448 | J17: ='Assumptions & Model'!$B$31+'Assumptions & Model'!$B$29*B17+'Assumptions & Model'!$B$30*C17 -> 97.058578 | K17: =E17-I17 -> 0.0037698443 | L17: =F17-J17 -> -0.027411791
A18: 17 | B18: 71 | C18: 53 | D18: =AVERAGE('Apache Raw'!R$2:R$25) -> 95.431583 | E18: =(SUM('Apache Raw'!R$2:R$25)-'Apache Raw'!R$17)/('Assumptions & Model'!$B$5-1) -> 95.445804 | F18: =AVERAGE('Odyssey Raw'!R$2:R$25) -> 97.141833 | G18: =IF(B18<33,"Low",IF(B18<67,"Medium","High")) -> High | H18: =IF(C18<33,"Low",IF(C18<67,"Medium","High")) -> Medium | I18: ='Assumptions & Model'!$B$28+'Assumptions & Model'!$B$26*B18+'Assumptions & Model'!$B$27*C18 -> 95.444382 | J18: ='Assumptions & Model'!$B$31+'Assumptions & Model'!$B$29*B18+'Assumptions & Model'!$B$30*C18 -> 97.151381 | K18: =E18-I18 -> 0.0014228041 | L18: =F18-J18 -> -0.0095471788
A19: 18 | B19: 87 | C19: 70 | D19: =AVERAGE('Apache Raw'!S$2:S$25) -> 95.496583 | E19: =(SUM('Apache Raw'!S$2:S$25)-'Apache Raw'!S$17)/('Assumptions & Model'!$B$5-1) -> 95.498196 | F19: =AVERAGE('Odyssey Raw'!S$2:S$25) -> 97.162917 | G19: =IF(B19<33,"Low",IF(B19<67,"Medium","High")) -> High | H19: =IF(C19<33,"Low",IF(C19<67,"Medium","High")) -> High | I19: ='Assumptions & Model'!$B$28+'Assumptions & Model'!$B$26*B19+'Assumptions & Model'!$B$27*C19 -> 95.527884 | J19: ='Assumptions & Model'!$B$31+'Assumptions & Model'!$B$29*B19+'Assumptions & Model'!$B$30*C19 -> 97.182853 | K19: =E19-I19 -> -0.0296888 | L19: =F19-J19 -> -0.019935893
A20: 19 | B20: 4 | C20: 26 | D20: =AVERAGE('Apache Raw'!T$2:T$25) -> 94.935583 | E20: =(SUM('Apache Raw'!T$2:T$25)-'Apache Raw'!T$17)/('Assumptions & Model'!$B$5-1) -> 94.936435 | F20: =AVERAGE('Odyssey Raw'!T$2:T$25) -> 97.044917 | G20: =IF(B20<33,"Low",IF(B20<67,"Medium","High")) -> Low | H20: =IF(C20<33,"Low",IF(C20<67,"Medium","High")) -> Low | I20: ='Assumptions & Model'!$B$28+'Assumptions & Model'!$B$26*B20+'Assumptions & Model'!$B$27*C20 -> 94.960646 | J20: ='Assumptions & Model'!$B$31+'Assumptions & Model'!$B$29*B20+'Assumptions & Model'!$B$30*C20 -> 96.998498 | K20: =E20-I20 -> -0.024211249 | L20: =F20-J20 -> 0.04641821
A21: 20 | B21: 92 | C21: 95 | D21: =AVERAGE('Apache Raw'!U$2:U$25) -> 95.46825 | E21: =(SUM('Apache Raw'!U$2:U$25)-'Apache Raw'!U$17)/('Assumptions & Model'!$B$5-1) -> 95.480043 | F21: =AVERAGE('Odyssey Raw'!U$2:U$25) -> 97.1825 | G21: =IF(B21<33,"Low",IF(B21<67,"Medium","High")) -> High | H21: =IF(C21<33,"Low",IF(C21<67,"Medium","High")) -> High | I21: ='Assumptions & Model'!$B$28+'Assumptions & Model'!$B$26*B21+'Assumptions & Model'!$B$27*C21 -> 95.494246 | J21: ='Assumptions & Model'!$B$31+'Assumptions & Model'!$B$29*B21+'Assumptions & Model'!$B$30*C21 -> 97.18329 | K21: =E21-I21 -> -0.014202772 | L21: =F21-J21 -> -0.00078976595
A22: 21 | B22: 41 | C22: 54 | D22: =AVERAGE('Apache Raw'!V$2:V$25) -> 95.156083 | E22: =(SUM('Apache Raw'!V$2:V$25)-'Apache Raw'!V$17)/('Assumptions & Model'!$B$5-1) -> 95.172152 | F22: =AVERAGE('Odyssey Raw'!V$2:V$25) -> 97.07675 | G22: =IF(B22<33,"Low",IF(B22<67,"Medium","High")) -> Medium | H22: =IF(C22<33,"Low",IF(C22<67,"Medium","High")) -> Medium | I22: ='Assumptions & Model'!$B$28+'Assumptions & Model'!$B$26*B22+'Assumptions & Model'!$B$27*C22 -> 95.188069 | J22: ='Assumptions & Model'!$B$31+'Assumptions & Model'!$B$29*B22+'Assumptions & Model'!$B$30*C22 -> 97.076678 | K22: =E22-I22 -> -0.015917023 | L22: =F22-J22 -> 7.2423883e-05
A23: 22 | B23: 76 | C23: 91 | D23: =AVERAGE('Apache Raw'!W$2:W$25) -> 95.374667 | E23: =(SUM('Apache Raw'!W$2:W$25)-'Apache Raw'!W$17)/('Assumptions & Model'!$B$5-1) -> 95.393435 | F23: =AVERAGE('Odyssey Raw'!W$2:W$25) -> 97.152833 | G23: =IF(B23<33,"Low",IF(B23<67,"Medium","High")) -> High | H23: =IF(C23<33,"Low",IF(C23<67,"Medium","High")) -> High | I23: ='Assumptions & Model'!$B$28+'Assumptions & Model'!$B$26*B23+'Assumptions & Model'!$B$27*C23 -> 95.371301 | J23: ='Assumptions & Model'!$B$31+'Assumptions & Model'!$B$29*B23+'Assumptions & Model'!$B$30*C23 -> 97.145612 | K23: =E23-I23 -> 0.02213409 | L23: =F23-J23 -> 0.0072211512
A24: 23 | B24: 82 | C24: 5 | D24: =AVERAGE('Apache Raw'!X$2:X$25) -> 95.670333 | E24: =(SUM('Apache Raw'!X$2:X$25)-'Apache Raw'!X$17)/('Assumptions & Model'!$B$5-1) -> 95.677217 | F24: =AVERAGE('Odyssey Raw'!X$2:X$25) -> 97.196667 | G24: =IF(B24<33,"Low",IF(B24<67,"Medium","High")) -> High | H24: =IF(C24<33,"Low",IF(C24<67,"Medium","High")) -> Low | I24: ='Assumptions & Model'!$B$28+'Assumptions & Model'!$B$26*B24+'Assumptions & Model'!$B$27*C24 -> 95.682885 | J24: ='Assumptions & Model'!$B$31+'Assumptions & Model'!$B$29*B24+'Assumptions & Model'!$B$30*C24 -> 97.201509 | K24: =E24-I24 -> -0.0056672624 | L24: =F24-J24 -> -0.0048426452
A25: 24 | B25: 39 | C25: 42 | D25: =AVERAGE('Apache Raw'!Y$2:Y$25) -> 95.202583 | E25: =(SUM('Apache Raw'!Y$2:Y$25)-'Apache Raw'!Y$17)/('Assumptions & Model'!$B$5-1) -> 95.209848 | F25: =AVERAGE('Odyssey Raw'!Y$2:Y$25) -> 97.095667 | G25: =IF(B25<33,"Low",IF(B25<67,"Medium","High")) -> Medium | H25: =IF(C25<33,"Low",IF(C25<67,"Medium","High")) -> Medium | I25: ='Assumptions & Model'!$B$28+'Assumptions & Model'!$B$26*B25+'Assumptions & Model'!$B$27*C25 -> 95.207593 | J25: ='Assumptions & Model'!$B$31+'Assumptions & Model'!$B$29*B25+'Assumptions & Model'!$B$30*C25 -> 97.077457 | K25: =E25-I25 -> 0.0022552488 | L25: =F25-J25 -> 0.018209275
A26: 25 | B26: 97 | C26: 68 | D26: =AVERAGE('Apache Raw'!Z$2:Z$25) -> 95.601333 | E26: =(SUM('Apache Raw'!Z$2:Z$25)-'Apache Raw'!Z$17)/('Assumptions & Model'!$B$5-1) -> 95.60963 | F26: =AVERAGE('Odyssey Raw'!Z$2:Z$25) -> 97.218917 | G26: =IF(B26<33,"Low",IF(B26<67,"Medium","High")) -> High | H26: =IF(C26<33,"Low",IF(C26<67,"Medium","High")) -> High | I26: ='Assumptions & Model'!$B$28+'Assumptions & Model'!$B$26*B26+'Assumptions & Model'!$B$27*C26 -> 95.618379 | J26: ='Assumptions & Model'!$B$31+'Assumptions & Model'!$B$29*B26+'Assumptions & Model'!$B$30*C26 -> 97.208549 | K26: =E26-I26 -> -0.008748216 | L26: =F26-J26 -> 0.010367547
A27: 26 | B27: 27 | C27: 15 | D27: =AVERAGE('Apache Raw'!AA$2:AA$25) -> 95.187417 | E27: =(SUM('Apache Raw'!AA$2:AA$25)-'Apache Raw'!AA$17)/('Assumptions & Model'!$B$5-1) -> 95.202326 | F27: =AVERAGE('Odyssey Raw'!AA$2:AA$25) -> 97.097917 | G27: =IF(B27<33,"Low",IF(B27<67,"Medium","High")) -> Low | H27: =IF(C27<33,"Low",IF(C27<67,"Medium","High")) -> Low | I27: ='Assumptions & Model'!$B$28+'Assumptions & Model'!$B$26*B27+'Assumptions & Model'!$B$27*C27 -> 95.188201 | J27: ='Assumptions & Model'!$B$31+'Assumptions & Model'!$B$29*B27+'Assumptions & Model'!$B$30*C27 -> 97.060656 | K27: =E27-I27 -> 0.014125478 | L27: =F27-J27 -> 0.037261088
A28: 27 | B28: 14 | C28: 57 | D28: =AVERAGE('Apache Raw'!AB$2:AB$25) -> 94.949667 | E28: =(SUM('Apache Raw'!AB$2:AB$25)-'Apache Raw'!AB$17)/('Assumptions & Model'!$B$5-1) -> 94.955391 | F28: =AVERAGE('Odyssey Raw'!AB$2:AB$25) -> 97.0015 | G28: =IF(B28<33,"Low",IF(B28<67,"Medium","High")) -> Low | H28: =IF(C28<33,"Low",IF(C28<67,"Medium","High")) -> Medium | I28: ='Assumptions & Model'!$B$28+'Assumptions & Model'!$B$26*B28+'Assumptions & Model'!$B$27*C28 -> 94.951017 | J28: ='Assumptions & Model'!$B$31+'Assumptions & Model'!$B$29*B28+'Assumptions & Model'!$B$30*C28 -> 97.008443 | K28: =E28-I28 -> 0.0043747248 | L28: =F28-J28 -> -0.0069425008
A29: 28 | B29: 44 | C29: 8 | D29: =AVERAGE('Apache Raw'!AC$2:AC$25) -> 95.33125 | E29: =(SUM('Apache Raw'!AC$2:AC$25)-'Apache Raw'!AC$17)/('Assumptions & Model'!$B$5-1) -> 95.343478 | F29: =AVERAGE('Odyssey Raw'!AC$2:AC$25) -> 97.126833 | G29: =IF(B29<33,"Low",IF(B29<67,"Medium","High")) -> Medium | H29: =IF(C29<33,"Low",IF(C29<67,"Medium","High")) -> Low | I29: ='Assumptions & Model'!$B$28+'Assumptions & Model'!$B$26*B29+'Assumptions & Model'!$B$27*C29 -> 95.352963 | J29: ='Assumptions & Model'!$B$31+'Assumptions & Model'!$B$29*B29+'Assumptions & Model'!$B$30*C29 -> 97.106058 | K29: =E29-I29 -> -0.0094850667 | L29: =F29-J29 -> 0.020775145
A30: 29 | B30: 15 | C30: 79 | D30: =AVERAGE('Apache Raw'!AD$2:AD$25) -> 94.857167 | E30: =(SUM('Apache Raw'!AD$2:AD$25)-'Apache Raw'!AD$17)/('Assumptions & Model'!$B$5-1) -> 94.870935 | F30: =AVERAGE('Odyssey Raw'!AD$2:AD$25) -> 96.992167 | G30: =IF(B30<33,"Low",IF(B30<67,"Medium","High")) -> Low | H30: =IF(C30<33,"Low",IF(C30<67,"Medium","High")) -> High | I30: ='Assumptions & Model'!$B$28+'Assumptions & Model'!$B$26*B30+'Assumptions & Model'!$B$27*C30 -> 94.89271 | J30: ='Assumptions & Model'!$B$31+'Assumptions & Model'!$B$29*B30+'Assumptions & Model'!$B$30*C30 -> 97.000415 | K30: =E30-I30 -> -0.021775306 | L30: =F30-J30 -> -0.0082483428
A31: 30 | B31: 62 | C31: 74 | D31: =AVERAGE('Apache Raw'!AE$2:AE$25) -> 95.31875 | E31: =(SUM('Apache Raw'!AE$2:AE$25)-'Apache Raw'!AE$17)/('Assumptions & Model'!$B$5-1) -> 95.322391 | F31: =AVERAGE('Odyssey Raw'!AE$2:AE$25) -> 97.132583 | G31: =IF(B31<33,"Low",IF(B31<67,"Medium","High")) -> Medium | H31: =IF(C31<33,"Low",IF(C31<67,"Medium","High")) -> High | I31: ='Assumptions & Model'!$B$28+'Assumptions & Model'!$B$26*B31+'Assumptions & Model'!$B$27*C31 -> 95.304683 | J31: ='Assumptions & Model'!$B$31+'Assumptions & Model'!$B$29*B31+'Assumptions & Model'!$B$30*C31 -> 97.119089 | K31: =E31-I31 -> 0.0177083 | L31: =F31-J31 -> 0.013494826
A32: 31 | B32: 39 | C32: 47 | D32: =AVERAGE('Apache Raw'!AF$2:AF$25) -> 95.18675 | E32: =(SUM('Apache Raw'!AF$2:AF$25)-'Apache Raw'!AF$17)/('Assumptions & Model'!$B$5-1) -> 95.192674 | F32: =AVERAGE('Odyssey Raw'!AF$2:AF$25) -> 97.051917 | G32: =IF(B32<33,"Low",IF(B32<67,"Medium","High")) -> Medium | H32: =IF(C32<33,"Low",IF(C32<67,"Medium","High")) -> Medium | I32: ='Assumptions & Model'!$B$28+'Assumptions & Model'!$B$26*B32+'Assumptions & Model'!$B$27*C32 -> 95.192422 | J32: ='Assumptions & Model'!$B$31+'Assumptions & Model'!$B$29*B32+'Assumptions & Model'!$B$30*C32 -> 97.075071 | K32: =E32-I32 -> 0.00025158587 | L32: =F32-J32 -> -0.02315398
A33: 32 | B33: 23 | C33: 84 | D33: =AVERAGE('Apache Raw'!AG$2:AG$25) -> 94.956833 | E33: =(SUM('Apache Raw'!AG$2:AG$25)-'Apache Raw'!AG$17)/('Assumptions & Model'!$B$5-1) -> 94.966978 | F33: =AVERAGE('Odyssey Raw'!AG$2:AG$25) -> 97.024667 | G33: =IF(B33<33,"Low",IF(B33<67,"Medium","High")) -> Low | H33: =IF(C33<33,"Low",IF(C33<67,"Medium","High")) -> High | I33: ='Assumptions & Model'!$B$28+'Assumptions & Model'!$B$26*B33+'Assumptions & Model'!$B$27*C33 -> 94.945081 | J33: ='Assumptions & Model'!$B$31+'Assumptions & Model'!$B$29*B33+'Assumptions & Model'!$B$30*C33 -> 97.017822 | K33: =E33-I33 -> 0.021897543 | L33: =F33-J33 -> 0.0068449122

Sheet Operator Analysis
A1: Operator | B1: Apache Avg | C1: Apache Peer Avg | D1: Apache Delta vs Peers | E1: Apache Z-Score | F1: Odyssey Avg | G1: Odyssey Peer Avg | H1: Odyssey Delta vs Peers | I1: Odyssey Z-Score | J1: Est. Apache Lost Units | K1: Est. Apache Revenue Impact | L1: Flag
A2: James | B2: =AVERAGE('Apache Raw'!B2:AG2) -> 95.325047 | C2: =(SUM($B$2:$B$25)-B2)/('Assumptions & Model'!$B$5-1) -> 95.267683 | D2: =B2-C2 -> 0.05736413 | E2: =(B2-AVERAGE($B$2:$B$25))/_xlfn.STDEV.S($B$2:$B$25) -> 1.0622191 | F2: =AVERAGE('Odyssey Raw'!B2:AG2) -> 97.110703 | G2: =(SUM($F$2:$F$25)-F2)/('Assumptions & Model'!$B$5-1) -> 97.098774 | H2: =F2-G2 -> 0.011929348 | I2: =(F2-AVERAGE($F$2:$F$25))/_xlfn.STDEV.S($F$2:$F$25) -> 0.63247498 | J2: =IF(E2<=-3,MAX(0,-D2)/100*'Assumptions & Model'!$B$3*'Assumptions & Model'!$B$4,0) -> 0 | K2: =J2*'Assumptions & Model'!$B$6 -> 0 | L2: =IF(AND(E2<=-3,ABS(I2)<3),"Investigate Apache",IF(I2<=-3,"Investigate Odyssey","Normal")) -> Normal
A3: Michael | B3: =AVERAGE('Apache Raw'!B3:AG3) -> 95.278172 | C3: =(SUM($B$2:$B$25)-B3)/('Assumptions & Model'!$B$5-1) -> 95.269721 | D3: =B3-C3 -> 0.008451087 | E3: =(B3-AVERAGE($B$2:$B$25))/_xlfn.STDEV.S($B$2:$B$25) -> 0.15648988 | F3: =AVERAGE('Odyssey Raw'!B3:AG3) -> 97.114141 | G3: =(SUM($F$2:$F$25)-F3)/('Assumptions & Model'!$B$5-1) -> 97.098624 | H3: =F3-G3 -> 0.015516304 | I3: =(F3-AVERAGE($F$2:$F$25))/_xlfn.STDEV.S($F$2:$F$25) -> 0.82264969 | J3: =IF(E3<=-3,MAX(0,-D3)/100*'Assumptions & Model'!$B$3*'Assumptions & Model'!$B$4,0) -> 0 | K3: =J3*'Assumptions & Model'!$B$6 -> 0 | L3: =IF(AND(E3<=-3,ABS(I3)<3),"Investigate Apache",IF(I3<=-3,"Investigate Odyssey","Normal")) -> Normal
A4: John | B4: =AVERAGE('Apache Raw'!B4:AG4) -> 95.301297 | C4: =(SUM($B$2:$B$25)-B4)/('Assumptions & Model'!$B$5-1) -> 95.268715 | D4: =B4-C4 -> 0.032581522 | E4: =(B4-AVERAGE($B$2:$B$25))/_xlfn.STDEV.S($B$2:$B$25) -> 0.60331629 | F4: =AVERAGE('Odyssey Raw'!B4:AG4) -> 97.130078 | G4: =(SUM($F$2:$F$25)-F4)/('Assumptions & Model'!$B$5-1) -> 97.097931 | H4: =F4-G4 -> 0.032146739 | I4: =(F4-AVERAGE($F$2:$F$25))/_xlfn.STDEV.S($F$2:$F$25) -> 1.7043688 | J4: =IF(E4<=-3,MAX(0,-D4)/100*'Assumptions & Model'!$B$3*'Assumptions & Model'!$B$4,0) -> 0 | K4: =J4*'Assumptions & Model'!$B$6 -> 0 | L4: =IF(AND(E4<=-3,ABS(I4)<3),"Investigate Apache",IF(I4<=-3,"Investigate Odyssey","Normal")) -> Normal
A5: Robert | B5: =AVERAGE('Apache Raw'!B5:AG5) -> 95.279109 | C5: =(SUM($B$2:$B$25)-B5)/('Assumptions & Model'!$B$5-1) -> 95.26968 | D5: =B5-C5 -> 0.0094293478 | E5: =(B5-AVERAGE($B$2:$B$25))/_xlfn.STDEV.S($B$2:$B$25) -> 0.17460447 | F5: =AVERAGE('Odyssey Raw'!B5:AG5) -> 97.087891 | G5: =(SUM($F$2:$F$25)-F5)/('Assumptions & Model'!$B$5-1) -> 97.099766 | H5: =F5-G5 -> -0.011875 | I5: =(F5-AVERAGE($F$2:$F$25))/_xlfn.STDEV.S($F$2:$F$25) -> -0.62959355 | J5: =IF(E5<=-3,MAX(0,-D5)/100*'Assumptions & Model'!$B$3*'Assumptions & Model'!$B$4,0) -> 0 | K5: =J5*'Assumptions & Model'!$B$6 -> 0 | L5: =IF(AND(E5<=-3,ABS(I5)<3),"Investigate Apache",IF(I5<=-3,"Investigate Odyssey","Normal")) -> Normal
A6: David | B6: =AVERAGE('Apache Raw'!B6:AG6) -> 95.286922 | C6: =(SUM($B$2:$B$25)-B6)/('Assumptions & Model'!$B$5-1) -> 95.26934 | D6: =B6-C6 -> 0.017581522 | E6: =(B6-AVERAGE($B$2:$B$25))/_xlfn.STDEV.S($B$2:$B$25) -> 0.32555933 | F6: =AVERAGE('Odyssey Raw'!B6:AG6) -> 97.074141 | G6: =(SUM($F$2:$F$25)-F6)/('Assumptions & Model'!$B$5-1) -> 97.100363 | H6: =F6-G6 -> -0.026222826 | I6: =(F6-AVERAGE($F$2:$F$25))/_xlfn.STDEV.S($F$2:$F$25) -> -1.3902924 | J6: =IF(E6<=-3,MAX(0,-D6)/100*'Assumptions & Model'!$B$3*'Assumptions & Model'!$B$4,0) -> 0 | K6: =J6*'Assumptions & Model'!$B$6 -> 0 | L6: =IF(AND(E6<=-3,ABS(I6)<3),"Investigate Apache",IF(I6<=-3,"Investigate Odyssey","Normal")) -> Normal
A7: William | B7: =AVERAGE('Apache Raw'!B7:AG7) -> 95.309734 | C7: =(SUM($B$2:$B$25)-B7)/('Assumptions & Model'!$B$5-1) -> 95.268349 | D7: =B7-C7 -> 0.04138587 | E7: =(B7-AVERAGE($B$2:$B$25))/_xlfn.STDEV.S($B$2:$B$25) -> 0.76634755 | F7: =AVERAGE('Odyssey Raw'!B7:AG7) -> 97.127266 | G7: =(SUM($F$2:$F$25)-F7)/('Assumptions & Model'!$B$5-1) -> 97.098054 | H7: =F7-G7 -> 0.029211957 | I7: =(F7-AVERAGE($F$2:$F$25))/_xlfn.STDEV.S($F$2:$F$25) -> 1.5487713 | J7: =IF(E7<=-3,MAX(0,-D7)/100*'Assumptions & Model'!$B$3*'Assumptions & Model'!$B$4,0) -> 0 | K7: =J7*'Assumptions & Model'!$B$6 -> 0 | L7: =IF(AND(E7<=-3,ABS(I7)<3),"Investigate Apache",IF(I7<=-3,"Investigate Odyssey","Normal")) -> Normal
A8: Richard | B8: =AVERAGE('Apache Raw'!B8:AG8) -> 95.259734 | C8: =(SUM($B$2:$B$25)-B8)/('Assumptions & Model'!$B$5-1) -> 95.270522 | D8: =B8-C8 -> -0.010788043 | E8: =(B8-AVERAGE($B$2:$B$25))/_xlfn.STDEV.S($B$2:$B$25) -> -0.19976361 | F8: =AVERAGE('Odyssey Raw'!B8:AG8) -> 97.101328 | G8: =(SUM($F$2:$F$25)-F8)/('Assumptions & Model'!$B$5-1) -> 97.099181 | H8: =F8-G8 -> 0.0021467391 | I8: =(F8-AVERAGE($F$2:$F$25))/_xlfn.STDEV.S($F$2:$F$25) -> 0.11381668 | J8: =IF(E8<=-3,MAX(0,-D8)/100*'Assumptions & Model'!$B$3*'Assumptions & Model'!$B$4,0) -> 0 | K8: =J8*'Assumptions & Model'!$B$6 -> 0 | L8: =IF(AND(E8<=-3,ABS(I8)<3),"Investigate Apache",IF(I8<=-3,"Investigate Odyssey","Normal")) -> Normal
A9: Joseph | B9: =AVERAGE('Apache Raw'!B9:AG9) -> 95.277547 | C9: =(SUM($B$2:$B$25)-B9)/('Assumptions & Model'!$B$5-1) -> 95.269748 | D9: =B9-C9 -> 0.007798913 | E9: =(B9-AVERAGE($B$2:$B$25))/_xlfn.STDEV.S($B$2:$B$25) -> 0.14441349 | F9: =AVERAGE('Odyssey Raw'!B9:AG9) -> 97.072266 | G9: =(SUM($F$2:$F$25)-F9)/('Assumptions & Model'!$B$5-1) -> 97.100445 | H9: =F9-G9 -> -0.028179348 | I9: =(F9-AVERAGE($F$2:$F$25))/_xlfn.STDEV.S($F$2:$F$25) -> -1.494024 | J9: =IF(E9<=-3,MAX(0,-D9)/100*'Assumptions & Model'!$B$3*'Assumptions & Model'!$B$4,0) -> 0 | K9: =J9*'Assumptions & Model'!$B$6 -> 0 | L9: =IF(AND(E9<=-3,ABS(I9)<3),"Investigate Apache",IF(I9<=-3,"Investigate Odyssey","Normal")) -> Normal
A10: Thomas | B10: =AVERAGE('Apache Raw'!B10:AG10) -> 95.284109 | C10: =(SUM($B$2:$B$25)-B10)/('Assumptions & Model'!$B$5-1) -> 95.269463 | D10: =B10-C10 -> 0.014646739 | E10: =(B10-AVERAGE($B$2:$B$25))/_xlfn.STDEV.S($B$2:$B$25) -> 0.27121558 | F10: =AVERAGE('Odyssey Raw'!B10:AG10) -> 97.108828 | G10: =(SUM($F$2:$F$25)-F10)/('Assumptions & Model'!$B$5-1) -> 97.098855 | H10: =F10-G10 -> 0.0099728261 | I10: =(F10-AVERAGE($F$2:$F$25))/_xlfn.STDEV.S($F$2:$F$25) -> 0.52874332 | J10: =IF(E10<=-3,MAX(0,-D10)/100*'Assumptions & Model'!$B$3*'Assumptions & Model'!$B$4,0) -> 0 | K10: =J10*'Assumptions & Model'!$B$6 -> 0 | L10: =IF(AND(E10<=-3,ABS(I10)<3),"Investigate Apache",IF(I10<=-3,"Investigate Odyssey","Normal")) -> Normal
A11: Christopher | B11: =AVERAGE('Apache Raw'!B11:AG11) -> 95.269109 | C11: =(SUM($B$2:$B$25)-B11)/('Assumptions & Model'!$B$5-1) -> 95.270115 | D11: =B11-C11 -> -0.0010054348 | E11: =(B11-AVERAGE($B$2:$B$25))/_xlfn.STDEV.S($B$2:$B$25) -> -0.018617767 | F11: =AVERAGE('Odyssey Raw'!B11:AG11) -> 97.076328 | G11: =(SUM($F$2:$F$25)-F11)/('Assumptions & Model'!$B$5-1) -> 97.100268 | H11: =F11-G11 -> -0.023940217 | I11: =(F11-AVERAGE($F$2:$F$25))/_xlfn.STDEV.S($F$2:$F$25) -> -1.2692721 | J11: =IF(E11<=-3,MAX(0,-D11)/100*'Assumptions & Model'!$B$3*'Assumptions & Model'!$B$4,0) -> 0 | K11: =J11*'Assumptions & Model'!$B$6 -> 0 | L11: =IF(AND(E11<=-3,ABS(I11)<3),"Investigate Apache",IF(I11<=-3,"Investigate Odyssey","Normal")) -> Normal
A12: Mary | B12: =AVERAGE('Apache Raw'!B12:AG12) -> 95.281609 | C12: =(SUM($B$2:$B$25)-B12)/('Assumptions & Model'!$B$5-1) -> 95.269571 | D12: =B12-C12 -> 0.012038043 | E12: =(B12-AVERAGE($B$2:$B$25))/_xlfn.STDEV.S($B$2:$B$25) -> 0.22291002 | F12: =AVERAGE('Odyssey Raw'!B12:AG12) -> 97.086641 | G12: =(SUM($F$2:$F$25)-F12)/('Assumptions & Model'!$B$5-1) -> 97.09982 | H12: =F12-G12 -> -0.013179348 | I12: =(F12-AVERAGE($F$2:$F$25))/_xlfn.STDEV.S($F$2:$F$25) -> -0.69874799 | J12: =IF(E12<=-3,MAX(0,-D12)/100*'Assumptions & Model'!$B$3*'Assumptions & Model'!$B$4,0) -> 0 | K12: =J12*'Assumptions & Model'!$B$6 -> 0 | L12: =IF(AND(E12<=-3,ABS(I12)<3),"Investigate Apache",IF(I12<=-3,"Investigate Odyssey","Normal")) -> Normal
A13: Patricia | B13: =AVERAGE('Apache Raw'!B13:AG13) -> 95.268484 | C13: =(SUM($B$2:$B$25)-B13)/('Assumptions & Model'!$B$5-1) -> 95.270142 | D13: =B13-C13 -> -0.0016576087 | E13: =(B13-AVERAGE($B$2:$B$25))/_xlfn.STDEV.S($B$2:$B$25) -> -0.030694157 | F13: =AVERAGE('Odyssey Raw'!B13:AG13) -> 97.070703 | G13: =(SUM($F$2:$F$25)-F13)/('Assumptions & Model'!$B$5-1) -> 97.100513 | H13: =F13-G13 -> -0.029809783 | I13: =(F13-AVERAGE($F$2:$F$25))/_xlfn.STDEV.S($F$2:$F$25) -> -1.5804671 | J13: =IF(E13<=-3,MAX(0,-D13)/100*'Assumptions & Model'!$B$3*'Assumptions & Model'!$B$4,0) -> 0 | K13: =J13*'Assumptions & Model'!$B$6 -> 0 | L13: =IF(AND(E13<=-3,ABS(I13)<3),"Investigate Apache",IF(I13<=-3,"Investigate Odyssey","Normal")) -> Normal
... A25: Amanda | B25: =AVERAGE('Apache Raw'!B25:AG25) -> 95.255359 | C25: =(SUM($B$2:$B$25)-B25)/('Assumptions & Model'!$B$5-1) -> 95.270713 | D25: =B25-C25 -> -0.015353261 | E25: =(B25-AVERAGE($B$2:$B$25))/_xlfn.STDEV.S($B$2:$B$25) -> -0.28429834 | F25: =AVERAGE('Odyssey Raw'!B25:AG25) -> 97.136641 | G25: =(SUM($F$2:$F$25)-F25)/('Assumptions & Model'!$B$5-1) -> 97.097646 | H25: =F25-G25 -> 0.038994565 | I25: =(F25-AVERAGE($F$2:$F$25))/_xlfn.STDEV.S($F$2:$F$25) -> 2.0674296 | J25: =IF(E25<=-3,MAX(0,-D25)/100*'Assumptions & Model'!$B$3*'Assumptions & Model'!$B$4,0) -> 0 | K25: =J25*'Assumptions & Model'!$B$6 -> 0 | L25: =IF(AND(E25<=-3,ABS(I25)<3),"Investigate Apache",IF(I25<=-3,"Investigate Odyssey","Normal")) -> Normal
A28: Barbara Detail — daily comparison to the other 23 operators | J28: Barbara checks | K28: Result
A29: Day | B29: Apache Barbara | C29: Apache Peer Avg | D29: Apache Diff | E29: Apache Lowest? | F29: Odyssey Barbara | G29: Odyssey Peer Avg | H29: Odyssey Diff | J29: Apache days below peer avg | K29: =COUNTIF($D$30:$D$61,"<0") -> 32
A30: 1 | B30: ='Apache Raw'!B$17 -> 95.189 | C30: =(SUM('Apache Raw'!B$2:B$25)-'Apache Raw'!B$17)/('Assumptions & Model'!$B$5-1) -> 95.460739 | D30: =B30-C30 -> -0.27173913 | E30: =IF(B30=MIN('Apache Raw'!B$2:B$25),1,0) -> 1 | F30: ='Odyssey Raw'!B$17 -> 97.3125 | G30: =(SUM('Odyssey Raw'!B$2:B$25)-'Odyssey Raw'!B$17)/('Assumptions & Model'!$B$5-1) -> 97.149457 | H30: =F30-G30 -> 0.16304348 | J30: Apache days with lowest yield | K30: =SUM($E$30:$E$61) -> 23
A31: 2 | B31: ='Apache Raw'!C$17 -> 94.6705 | C31: =(SUM('Apache Raw'!C$2:C$25)-'Apache Raw'!C$17)/('Assumptions & Model'!$B$5-1) -> 95.027891 | D31: =B31-C31 -> -0.3573913 | E31: =IF(B31=MIN('Apache Raw'!C$2:C$25),1,0) -> 1 | F31: ='Odyssey Raw'!C$17 -> 96.8105 | G31: =(SUM('Odyssey Raw'!C$2:C$25)-'Odyssey Raw'!C$17)/('Assumptions & Model'!$B$5-1) -> 96.97963 | H31: =F31-G31 -> -0.16913043 | J31: Odyssey avg delta vs peers | K31: =AVERAGE($H$30:$H$61) -> 0.0047554348
A32: 3 | B32: ='Apache Raw'!D$17 -> 94.6555 | C32: =(SUM('Apache Raw'!D$2:D$25)-'Apache Raw'!D$17)/('Assumptions & Model'!$B$5-1) -> 94.93637 | D32: =B32-C32 -> -0.28086957 | E32: =IF(B32=MIN('Apache Raw'!D$2:D$25),1,0) -> 1 | F32: ='Odyssey Raw'!D$17 -> 97.112 | G32: =(SUM('Odyssey Raw'!D$2:D$25)-'Odyssey Raw'!D$17)/('Assumptions & Model'!$B$5-1) -> 96.968087 | H32: =F32-G32 -> 0.14391304
A33: 4 | B33: ='Apache Raw'!E$17 -> 94.9455 | C33: =(SUM('Apache Raw'!E$2:E$25)-'Apache Raw'!E$17)/('Assumptions & Model'!$B$5-1) -> 95.198543 | D33: =B33-C33 -> -0.25304348 | E33: =IF(B33=MIN('Apache Raw'!E$2:E$25),1,0) -> 1 | F33: ='Odyssey Raw'!E$17 -> 96.9175 | G33: =(SUM('Odyssey Raw'!E$2:E$25)-'Odyssey Raw'!E$17)/('Assumptions & Model'!$B$5-1) -> 97.039239 | H33: =F33-G33 -> -0.12173913
A34: 5 | B34: ='Apache Raw'!F$17 -> 95.3865 | C34: =(SUM('Apache Raw'!F$2:F$25)-'Apache Raw'!F$17)/('Assumptions & Model'!$B$5-1) -> 95.642152 | D34: =B34-C34 -> -0.25565217 | E34: =IF(B34=MIN('Apache Raw'!F$2:F$25),1,0) -> 1 | F34: ='Odyssey Raw'!F$17 -> 97.0495 | G34: =(SUM('Odyssey Raw'!F$2:F$25)-'Odyssey Raw'!F$17)/('Assumptions & Model'!$B$5-1) -> 97.191239 | H34: =F34-G34 -> -0.14173913
A35: 6 | B35: ='Apache Raw'!G$17 -> 95.2685 | C35: =(SUM('Apache Raw'!G$2:G$25)-'Apache Raw'!G$17)/('Assumptions & Model'!$B$5-1) -> 95.596761 | D35: =B35-C35 -> -0.32826087 | E35: =IF(B35=MIN('Apache Raw'!G$2:G$25),1,0) -> 1 | F35: ='Odyssey Raw'!G$17 -> 97.1715 | G35: =(SUM('Odyssey Raw'!G$2:G$25)-'Odyssey Raw'!G$17)/('Assumptions & Model'!$B$5-1) -> 97.198022 | H35: =F35-G35 -> -0.026521739
A36: 7 | B36: ='Apache Raw'!H$17 -> 94.795 | C36: =(SUM('Apache Raw'!H$2:H$25)-'Apache Raw'!H$17)/('Assumptions & Model'!$B$5-1) -> 95.026304 | D36: =B36-C36 -> -0.23130435 | E36: =IF(B36=MIN('Apache Raw'!H$2:H$25),1,0) -> 1 | F36: ='Odyssey Raw'!H$17 -> 96.945 | G36: =(SUM('Odyssey Raw'!H$2:H$25)-'Odyssey Raw'!H$17)/('Assumptions & Model'!$B$5-1) -> 97.059348 | H36: =F36-G36 -> -0.11434783
A37: 8 | B37: ='Apache Raw'!I$17 -> 95.587 | C37: =(SUM('Apache Raw'!I$2:I$25)-'Apache Raw'!I$17)/('Assumptions & Model'!$B$5-1) -> 95.763522 | D37: =B37-C37 -> -0.17652174 | E37: =IF(B37=MIN('Apache Raw'!I$2:I$25),1,0) -> 1 | F37: ='Odyssey Raw'!I$17 -> 97.242 | G37: =(SUM('Odyssey Raw'!I$2:I$25)-'Odyssey Raw'!I$17)/('Assumptions & Model'!$B$5-1) -> 97.208522 | H37: =F37-G37 -> 0.033478261
A38: 9 | B38: ='Apache Raw'!J$17 -> 95.023 | C38: =(SUM('Apache Raw'!J$2:J$25)-'Apache Raw'!J$17)/('Assumptions & Model'!$B$5-1) -> 95.230826 | D38: =B38-C38 -> -0.20782609 | E38: =IF(B38=MIN('Apache Raw'!J$2:J$25),1,0) -> 1 | F38: ='Odyssey Raw'!J$17 -> 96.9995 | G38: =(SUM('Odyssey Raw'!J$2:J$25)-'Odyssey Raw'!J$17)/('Assumptions & Model'!$B$5-1) -> 97.047761 | H38: =F38-G38 -> -0.04826087
A39: 10 | B39: ='Apache Raw'!K$17 -> 94.6775 | C39: =(SUM('Apache Raw'!K$2:K$25)-'Apache Raw'!K$17)/('Assumptions & Model'!$B$5-1) -> 94.979674 | D39: =B39-C39 -> -0.30217391 | E39: =IF(B39=MIN('Apache Raw'!K$2:K$25),1,0) -> 1 | F39: ='Odyssey Raw'!K$17 -> 97.181 | G39: =(SUM('Odyssey Raw'!K$2:K$25)-'Odyssey Raw'!K$17)/('Assumptions & Model'!$B$5-1) -> 97.006217 | H39: =F39-G39 -> 0.17478261
A40: 11 | B40: ='Apache Raw'!L$17 -> 95.066 | C40: =(SUM('Apache Raw'!L$2:L$25)-'Apache Raw'!L$17)/('Assumptions & Model'!$B$5-1) -> 95.472957 | D40: =B40-C40 -> -0.40695652 | E40: =IF(B40=MIN('Apache Raw'!L$2:L$25),1,0) -> 1 | F40: ='Odyssey Raw'!L$17 -> 97.0385 | G40: =(SUM('Odyssey Raw'!L$2:L$25)-'Odyssey Raw'!L$17)/('Assumptions & Model'!$B$5-1) -> 97.17937 | H40: =F40-G40 -> -0.14086957
A41: 12 | B41: ='Apache Raw'!M$17 -> 94.9825 | C41: =(SUM('Apache Raw'!M$2:M$25)-'Apache Raw'!M$17)/('Assumptions & Model'!$B$5-1) -> 95.074674 | D41: =B41-C41 -> -0.092173913 | E41: =IF(B41=MIN('Apache Raw'!M$2:M$25),1,0) -> 0 | F41: ='Odyssey Raw'!M$17 -> 97.186 | G41: =(SUM('Odyssey Raw'!M$2:M$25)-'Odyssey Raw'!M$17)/('Assumptions & Model'!$B$5-1) -> 97.038609 | H41: =F41-G41 -> 0.1473913
A42: 13 | B42: ='Apache Raw'!N$17 -> 95.1165 | C42: =(SUM('Apache Raw'!N$2:N$25)-'Apache Raw'!N$17)/('Assumptions & Model'!$B$5-1) -> 95.384761 | D42: =B42-C42 -> -0.26826087 | E42: =IF(B42=MIN('Apache Raw'!N$2:N$25),1,0) -> 1 | F42: ='Odyssey Raw'!N$17 -> 97.091 | G42: =(SUM('Odyssey Raw'!N$2:N$25)-'Odyssey Raw'!N$17)/('Assumptions & Model'!$B$5-1) -> 97.142304 | H42: =F42-G42 -> -0.051304348
A43: 14 | B43: ='Apache Raw'!O$17 -> 95.0315 | C43: =(SUM('Apache Raw'!O$2:O$25)-'Apache Raw'!O$17)/('Assumptions & Model'!$B$5-1) -> 95.145848 | D43: =B43-C43 -> -0.11434783 | E43: =IF(B43=MIN('Apache Raw'!O$2:O$25),1,0) -> 0 | F43: ='Odyssey Raw'!O$17 -> 97.048 | G43: =(SUM('Odyssey Raw'!O$2:O$25)-'Odyssey Raw'!O$17)/('Assumptions & Model'!$B$5-1) -> 97.012783 | H43: =F43-G43 -> 0.035217391
A44: 15 | B44: ='Apache Raw'!P$17 -> 95.3625 | C44: =(SUM('Apache Raw'!P$2:P$25)-'Apache Raw'!P$17)/('Assumptions & Model'!$B$5-1) -> 95.629022 | D44: =B44-C44 -> -0.26652174 | E44: =IF(B44=MIN('Apache Raw'!P$2:P$25),1,0) -> 1 | F44: ='Odyssey Raw'!P$17 -> 97.3525 | G44: =(SUM('Odyssey Raw'!P$2:P$25)-'Odyssey Raw'!P$17)/('Assumptions & Model'!$B$5-1) -> 97.223804 | H44: =F44-G44 -> 0.12869565
A45: 16 | B45: ='Apache Raw'!Q$17 -> 94.948 | C45: =(SUM('Apache Raw'!Q$2:Q$25)-'Apache Raw'!Q$17)/('Assumptions & Model'!$B$5-1) -> 95.113217 | D45: =B45-C45 -> -0.16521739 | E45: =IF(B45=MIN('Apache Raw'!Q$2:Q$25),1,0) -> 0 | F45: ='Odyssey Raw'!Q$17 -> 96.897 | G45: =(SUM('Odyssey Raw'!Q$2:Q$25)-'Odyssey Raw'!Q$17)/('Assumptions & Model'!$B$5-1) -> 97.037 | H45: =F45-G45 -> -0.14
A46: 17 | B46: ='Apache Raw'!R$17 -> 95.1045 | C46: =(SUM('Apache Raw'!R$2:R$25)-'Apache Raw'!R$17)/('Assumptions & Model'!$B$5-1) -> 95.445804 | D46: =B46-C46 -> -0.34130435 | E46: =IF(B46=MIN('Apache Raw'!R$2:R$25),1,0) -> 1 | F46: ='Odyssey Raw'!R$17 -> 96.951 | G46: =(SUM('Odyssey Raw'!R$2:R$25)-'Odyssey Raw'!R$17)/('Assumptions & Model'!$B$5-1) -> 97.15013 | H46: =F46-G46 -> -0.19913043
A47: 18 | B47: ='Apache Raw'!S$17 -> 95.4595 | C47: =(SUM('Apache Raw'!S$2:S$25)-'Apache Raw'!S$17)/('Assumptions & Model'!$B$5-1) -> 95.498196 | D47: =B47-C47 -> -0.038695652 | E47: =IF(B47=MIN('Apache Raw'!S$2:S$25),1,0) -> 0 | F47: ='Odyssey Raw'!S$17 -> 97.0225 | G47: =(SUM('Odyssey Raw'!S$2:S$25)-'Odyssey Raw'!S$17)/('Assumptions & Model'!$B$5-1) -> 97.169022 | H47: =F47-G47 -> -0.14652174
A48: 19 | B48: ='Apache Raw'!T$17 -> 94.916 | C48: =(SUM('Apache Raw'!T$2:T$25)-'Apache Raw'!T$17)/('Assumptions & Model'!$B$5-1) -> 94.936435 | D48: =B48-C48 -> -0.020434783 | E48: =IF(B48=MIN('Apache Raw'!T$2:T$25),1,0) -> 0 | F48: ='Odyssey Raw'!T$17 -> 97.157 | G48: =(SUM('Odyssey Raw'!T$2:T$25)-'Odyssey Raw'!T$17)/('Assumptions & Model'!$B$5-1) -> 97.040043 | H48: =F48-G48 -> 0.11695652
A49: 20 | B49: ='Apache Raw'!U$17 -> 95.197 | C49: =(SUM('Apache Raw'!U$2:U$25)-'Apache Raw'!U$17)/('Assumptions & Model'!$B$5-1) -> 95.480043 | D49: =B49-C49 -> -0.28304348 | E49: =IF(B49=MIN('Apache Raw'!U$2:U$25),1,0) -> 1 | F49: ='Odyssey Raw'!U$17 -> 97.3325 | G49: =(SUM('Odyssey Raw'!U$2:U$25)-'Odyssey Raw'!U$17)/('Assumptions & Model'!$B$5-1) -> 97.175978 | H49: =F49-G49 -> 0.15652174
A50: 21 | B50: ='Apache Raw'!V$17 -> 94.7865 | C50: =(SUM('Apache Raw'!V$2:V$25)-'Apache Raw'!V$17)/('Assumptions & Model'!$B$5-1) -> 95.172152 | D50: =B50-C50 -> -0.38565217 | E50: =IF(B50=MIN('Apache Raw'!V$2:V$25),1,0) -> 1 | F50: ='Odyssey Raw'!V$17 -> 97.1955 | G50: =(SUM('Odyssey Raw'!V$2:V$25)-'Odyssey Raw'!V$17)/('Assumptions & Model'!$B$5-1) -> 97.071587 | H50: =F50-G50 -> 0.12391304
A51: 22 | B51: ='Apache Raw'!W$17 -> 94.943 | C51: =(SUM('Apache Raw'!W$2:W$25)-'Apache Raw'!W$17)/('Assumptions & Model'!$B$5-1) -> 95.393435 | D51: =B51-C51 -> -0.45043478 | E51: =IF(B51=MIN('Apache Raw'!W$2:W$25),1,0) -> 1 | F51: ='Odyssey Raw'!W$17 -> 97.2445 | G51: =(SUM('Odyssey Raw'!W$2:W$25)-'Odyssey Raw'!W$17)/('Assumptions & Model'!$B$5-1) -> 97.148848 | H51: =F51-G51 -> 0.095652174
